tests/64_threads/sample_67.in
64
o
33 B 101 1 120 774
1 S 104 6 178 230
15 B 105 6 115 985
17 B 106 7 138 377
22 S 107 0 120 320
23 S 108 8 186 244
47 S 109 8 153 671
44 B 110 2 128 762
38 B 111 6 120 160
28 S 112 7 106 599
53 S 114 2 133 432
25 S 115 5 189 891
15 B 116 8 128 238
44 S 117 1 140 718
13 B 118 5 179 451
10 B 119 0 165 431
32 S 120 9 187 593
8 S 121 5 136 745
33 C 101
13 B 123 6 154 476
37 S 125 8 131 424
31 S 126 6 130 109
8 C 121
8 S 128 3 119 360
59 B 129 2 173 406
59 C 129
20 B 131 7 166 86
31 C 126
20 B 134 4 150 45
37 C 125
37 C 125
18 S 138 5 188 443
10 S 139 9 144 689
26 S 140 8 107 363
28 C 112
33 C 101
23 S 143 8 113 212
22 S 144 2 114 176
37 C 125
25 C 115
24 S 147 4 111 132
28 C 112
22 C 144
23 S 152 1 125 118
24 C 147
37 C 125
28 S 157 1 160 231
49 B 158 6 174 764
12 B 159 8 160 630
26 B 161 3 180 601
24 C 147
29 S 163 9 127 956
37 B 164 9 104 976
48 S 165 9 126 679
16 B 167 1 150 31
52 S 169 5 125 41
26 B 170 3 148 976
7 S 171 7 121 352
37 C 164
49 S 173 6 197 391
58 S 174 2 119 485
4 B 175 7 128 851
34 B 176 8 141 847
36 S 177 7 168 54
10 B 178 0 119 886
35 S 179 8 139 570
8 B 180 4 149 670
44 C 117
41 B 182 9 100 280
28 S 183 0 182 152
50 S 184 7 181 686
11 S 185 0 196 125
53 S 186 8 122 761
16 C 167
55 S 188 4 200 581
25 C 115
10 S 190 1 153 536
25 S 191 3 156 673
18 C 138
30 S 193 1 112 703
17 C 106
34 S 196 8 148 28
44 C 117
1 B 199 8 192 685
22 C 107
29 B 204 6 183 607
20 B 205 5 135 765
47 B 206 0 186 484
15 B 207 1 157 596
22 B 208 2 167 656
58 B 209 7 147 908
29 S 210 7 188 63
43 S 211 8 132 832
63 S 214 0 162 496
8 B 215 6 143 613
43 C 211
38 C 111
18 C 138
33 B 219 9 181 771
49 S 220 3 145 383
45 B 221 2 155 868
0 S 222 9 166 501
21 S 223 3 174 414
9 B 224 1 147 737
25 B 225 1 132 459
44 C 117
35 S 227 8 112 54
51 B 228 3 169 656
10 B 229 6 125 226
45 B 231 9 195 189
52 S 232 3 117 33
22 S 233 0 153 101
5 B 234 1 105 517
7 C 171
15 C 207
11 B 238 6 155 805
17 S 239 5 146 941
22 C 208
37 C 125
10 S 242 6 117 952
26 S 243 2 144 311
50 S 244 6 165 504
48 C 165
21 C 223
25 S 247 3 147 385
13 C 123
21 C 223
52 C 169
34 B 252 2 101 451
62 B 253 7 103 969
29 B 254 7 146 842
24 B 255 2 161 434
6 B 256 4 107 134
18 C 138
45 B 258 8 128 161
30 B 259 7 183 884
32 S 260 0 105 839
5 C 234
24 S 262 3 200 729
9 B 263 6 120 492
15 C 105
21 C 223
25 S 267 2 103 43
33 C 101
53 B 269 0 133 334
22 S 270 8 134 739
45 S 271 4 167 466
37 S 272 2 104 798
10 C 178
17 B 274 3 197 724
38 C 111
15 S 276 1 197 536
63 B 277 8 163 639
63 C 214
5 C 234
57 B 280 4 100 462
2 S 281 8 113 396
40 B 282 2 118 875
40 S 283 5 173 550
34 B 284 4 160 494
38 S 285 3 147 273
35 C 179
3 B 287 4 137 124
11 S 288 9 124 776
60 S 289 7 143 383
50 B 291 8 172 943
12 B 292 5 134 177
35 B 293 2 181 727
49 B 294 2 164 467
35 S 295 9 106 396
31 C 126
15 B 297 9 148 550
63 C 214
49 S 299 0 155 959
32 S 300 8 137 193
6 B 301 5 127 681
25 S 302 9 148 575
27 S 303 1 177 976
54 B 304 9 112 595
20 B 305 1 186 888
23 B 306 7 182 932
22 S 307 2 166 195
49 S 308 7 127 123
6 C 256
60 C 289
24 S 311 7 128 238
15 S 312 3 148 734
10 S 313 0 150 68
38 C 285
62 S 315 9 148 128
58 C 209
57 B 317 2 116 935
23 B 318 7 109 283
27 B 319 6 146 395
2 B 320 3 126 98
10 B 321 1 191 653
10 S 322 2 146 956
54 S 323 7 173 102
16 B 324 8 161 911
43 B 325 6 191 234
37 C 164
32 C 120
58 C 209
22 S 329 8 144 456
52 C 232
56 S 331 6 165 456
4 S 332 8 169 40
17 S 333 1 150 126
55 C 188
24 C 262
12 B 336 8 120 153
32 S 337 3 187 363
35 B 338 5 116 219
25 S 339 9 124 322
1 C 199
22 S 341 0 166 831
1 S 342 3 162 798
4 C 332
30 B 344 3 100 517
7 B 345 1 195 115
11 S 346 6 182 392
61 S 347 5 172 954
63 C 214
51 C 228
11 B 350 2 172 626
51 B 351 6 168 96
38 B 352 6 162 312
52 S 353 6 159 742
38 B 354 4 136 168
3 C 287
60 B 356 2 166 409
48 C 165
57 S 358 5 128 996
33 S 359 2 147 631
43 B 360 2 116 85
4 S 361 8 153 260
6 C 256
17 B 363 7 169 899
3 S 364 2 153 928
20 B 365 6 199 752
47 B 366 4 146 911
2 S 367 1 200 137
18 S 368 2 111 756
11 S 369 8 145 952
26 S 370 4 158 150
53 B 371 3 182 649
51 S 372 5 108 114
16 B 373 5 147 602
55 B 374 4 135 587
21 B 375 4 170 799
0 B 376 8 118 768
25 S 377 8 126 483
3 C 364
4 C 332
24 S 380 4 184 582
43 S 381 5 152 541
26 C 370
4 B 383 5 145 227
9 S 384 5 144 494
56 B 385 3 134 14
4 B 386 7 117 595
2 S 387 2 177 489
51 C 351
35 B 389 0 152 28
9 C 263
10 C 313
14 S 392 0 122 477
22 S 393 6 173 923
45 S 394 7 173 974
57 B 395 8 183 979
32 B 396 0 175 940
9 S 397 6 109 929
47 S 398 0 122 484
9 C 397
38 C 111
59 B 401 3 181 587
45 B 402 1 138 764
20 B 403 2 115 772
10 C 178
53 S 405 0 123 854
25 B 406 4 134 183
26 C 161
22 S 409 0 182 418
45 B 410 8 129 948
16 B 411 9 194 957
9 S 412 0 114 524
3 C 364
55 S 414 5 105 537
36 S 415 1 157 974
22 B 416 8 190 378
32 C 120
54 S 418 3 102 96
13 S 419 3 102 939
59 C 129
29 S 421 0 133 567
47 S 422 0 142 533
0 S 423 7 115 268
15 C 276
22 B 425 5 125 271
41 B 426 0 182 575
41 C 182
4 B 428 4 164 994
24 S 429 4 170 479
60 S 430 8 184 60
48 B 431 5 150 702
56 B 432 7 163 686
14 C 392
24 C 380
25 B 435 7 193 716
53 S 436 6 102 164
57 C 317
29 S 438 3 197 705
49 C 299
54 S 440 4 128 105
34 S 441 5 173 186
46 B 442 2 172 921
9 B 443 7 169 87
1 S 444 4 164 693
45 B 445 7 166 455
50 C 291
22 S 447 3 176 561
57 S 448 2 193 207
20 C 205
59 S 450 7 180 555
30 S 451 7 190 82
26 C 170
44 B 453 6 136 753
56 C 331
37 S 455 1 191 125
29 S 456 2 151 767
9 C 263
29 B 458 1 150 649
24 B 459 2 191 413
55 C 374
5 B 461 1 181 395
30 C 193
56 C 432
16 C 411
44 S 465 6 170 999
58 B 466 5 135 734
45 B 467 9 116 253
47 S 468 4 119 707
4 B 469 3 159 638
10 B 470 3 157 782
49 C 173
34 C 176
32 S 473 6 152 574
10 S 474 7 119 182
24 B 475 2 164 868
24 S 477 0 114 43
23 B 478 4 196 256
61 B 479 9 185 507
10 B 480 9 103 51
63 B 481 7 157 332
18 S 482 9 120 923
49 B 483 1 153 343
47 S 484 5 164 749
12 B 485 0 132 691
5 S 486 9 147 746
53 S 487 3 141 694
18 B 488 1 105 742
30 B 489 0 146 779
6 B 490 5 114 635
25 C 225
27 S 492 9 100 15
37 B 493 1 122 968
43 S 494 0 163 993
15 C 116
37 B 496 9 177 186
22 S 497 5 102 897
3 B 498 8 199 959
16 B 499 0 110 845
42 B 500 1 110 279
11 C 346
11 C 288
15 C 312
48 C 165
32 C 120
60 S 506 7 186 921
5 S 507 2 141 270
26 C 370
25 B 509 6 200 765
25 B 510 3 140 269
44 S 511 5 164 714
39 S 512 1 156 674
0 C 423
61 C 479
15 B 515 4 102 75
34 B 516 0 149 969
22 C 497
23 C 318
5 B 519 7 175 955
30 B 520 0 106 139
2 S 521 7 172 87
42 S 522 1 118 271
41 S 523 9 125 200
28 S 524 3 136 292
45 S 525 6 173 16
36 C 177
60 S 527 3 151 942
47 C 366
54 S 529 3 129 691
47 S 530 0 152 927
50 B 531 5 139 516
23 B 532 1 178 962
28 B 533 5 182 927
7 C 345
28 S 535 4 178 309
40 C 283
38 C 352
21 C 223
63 S 539 7 148 753
51 B 540 5 200 346
26 S 541 6 113 827
40 S 542 4 103 254
51 S 543 7 184 30
53 C 487
2 S 545 6 152 621
31 C 126
29 S 547 2 111 22
41 B 548 6 180 603
33 C 359
17 B 550 0 161 118
10 S 551 8 129 182
4 B 552 3 186 689
42 S 553 8 170 84
28 C 524
39 B 555 9 147 839
40 S 556 2 123 641
17 B 557 0 127 272
6 B 558 2 168 424
26 C 140
53 B 560 5 112 392
4 B 561 2 100 670
51 S 562 9 170 626
44 B 563 2 183 165
25 C 377
46 B 565 4 177 926
35 S 566 8 111 698
34 C 284
34 B 568 8 198 307
10 C 480
0 C 222
15 S 571 4 197 840
41 B 572 1 180 503
4 S 573 5 149 601
18 S 574 5 190 926
9 C 263
45 C 402
25 S 577 8 108 613
21 S 578 1 140 71
37 B 579 2 145 605
44 B 580 7 172 18
49 C 294
61 C 479
37 S 583 2 166 131
7 C 345
13 S 585 9 199 230
29 S 586 0 156 220
31 C 126
62 C 315
41 C 572
36 C 415
50 S 591 2 141 874
21 C 578
36 S 593 3 108 322
42 S 594 3 160 770
14 S 595 2 158 241
33 S 596 8 130 485
2 C 320
51 S 598 2 122 452
26 S 599 6 164 783
6 S 600 5 189 189
33 B 601 8 129 816
46 B 602 6 170 211
19 S 603 7 139 546
55 S 604 3 198 131
62 B 605 1 178 222
35 C 295
39 S 607 4 125 87
32 C 300
48 B 609 1 109 558
54 C 304
48 S 611 4 180 798
23 B 612 5 126 538
5 C 234
4 B 614 2 178 858
58 S 615 8 127 829
40 S 616 9 166 669
43 S 617 8 181 75
0 B 618 7 126 92
39 C 555
43 S 620 5 124 11
31 C 126
20 B 622 1 185 537
0 B 623 1 151 482
61 S 624 0 195 311
13 B 625 5 136 773
47 C 422
49 B 627 7 196 302
35 C 179
