tests/64_threads/sample_68.in
64
o
32 S 102 1 175 587
34 B 103 9 165 296
57 S 104 5 138 804
28 B 106 1 159 541
18 S 107 0 110 746
6 B 109 0 144 44
51 B 111 6 167 256
32 S 112 3 160 819
62 S 114 9 105 143
25 B 116 7 123 377
42 B 117 1 189 450
54 B 118 0 145 830
8 B 119 7 168 808
61 S 120 1 108 853
27 B 121 2 110 420
49 S 122 2 191 659
33 S 125 0 178 702
14 B 126 5 167 175
17 S 128 8 128 673
14 C 126
12 B 131 6 103 936
54 S 132 8 126 521
18 S 133 0 144 676
57 B 135 9 137 791
1 B 136 1 104 888
27 S 138 8 100 597
10 B 139 1 135 279
62 B 140 1 161 119
51 C 111
9 B 142 9 195 968
57 C 104
56 B 144 6 114 403
58 B 149 6 200 619
46 S 150 1 191 714
1 S 151 8 187 579
44 B 152 7 124 503
32 B 153 3 168 839
35 B 154 2 170 488
33 B 155 6 158 800
34 C 103
37 B 157 2 183 130
31 B 158 8 100 476
55 S 159 6 190 549
3 S 160 0 164 581
58 C 149
50 B 162 2 134 463
44 S 163 3 195 77
18 B 164 9 192 883
61 S 165 4 126 865
42 C 117
6 C 109
24 S 168 7 195 178
54 B 169 7 129 596
28 C 106
3 B 171 6 120 751
48 S 172 4 152 100
15 B 174 7 187 395
27 S 175 9 156 432
54 S 176 0 137 526
33 C 155
25 B 178 5 191 727
24 C 168
63 B 181 0 161 533
54 C 132
44 B 183 0 199 750
13 S 184 1 111 88
41 S 185 2 119 558
9 S 186 8 105 20
59 S 187 8 185 416
60 B 188 3 132 513
12 C 131
0 S 190 2 128 674
5 S 191 6 125 787
43 S 192 7 175 651
36 S 194 8 130 189
19 B 195 8 187 259
27 B 196 1 110 431
4 B 197 6 180 154
28 B 199 9 166 667
11 S 200 4 193 455
6 S 201 5 185 564
32 B 202 2 115 460
33 B 203 6 159 62
31 S 204 2 180 544
37 C 157
1 B 207 0 136 957
2 B 208 8 185 772
63 B 209 6 183 830
18 B 210 5 149 292
51 C 111
51 B 212 6 131 948
32 S 213 5 184 405
35 B 214 0 159 197
26 S 215 6 126 569
50 S 216 4 106 940
8 C 119
21 S 218 3 141 843
48 S 219 6 192 83
33 B 221 4 148 145
33 C 155
46 B 223 1 185 380
38 S 224 6 185 692
44 S 225 9 113 633
54 B 226 0 137 980
21 C 218
13 C 184
19 C 195
34 C 103
60 B 232 5 153 499
43 C 192
44 S 234 2 182 334
2 S 235 1 180 581
63 C 209
54 C 118
28 S 238 8 188 190
58 C 149
37 C 157
18 S 241 9 104 413
61 B 242 4 179 628
40 B 243 8 100 719
38 B 244 3 145 791
26 S 246 9 140 462
37 B 247 1 110 743
36 B 248 4 135 434
0 B 249 9 139 804
31 C 158
46 S 251 6 175 388
31 C 204
41 B 253 4 117 686
10 B 254 1 144 443
1 S 255 9 176 227
37 B 256 3 185 767
34 B 257 5 157 751
37 B 258 7 194 791
35 S 259 5 154 136
46 S 261 3 151 196
59 S 262 6 127 764
10 S 264 9 101 269
8 C 119
31 B 266 9 192 717
25 B 267 8 183 322
34 B 268 5 109 685
3 S 270 5 196 297
35 S 271 6 193 333
11 S 272 3 182 575
27 B 273 9 152 422
31 B 276 2 153 957
9 B 277 0 181 59
13 S 278 3 108 408
44 C 152
38 S 280 2 193 598
38 C 244
63 B 282 1 111 586
2 C 235
44 S 284 3 152 494
37 S 285 1 114 539
55 C 159
46 S 288 7 184 305
12 C 131
50 C 216
44 B 291 2 123 135
22 B 293 1 167 830
13 S 294 5 154 786
25 B 295 8 199 485
27 B 296 8 107 709
1 S 298 9 178 535
17 B 299 3 200 98
21 C 218
18 B 301 8 102 220
14 S 302 8 162 330
24 C 168
29 B 304 1 152 582
27 S 305 8 170 949
36 B 306 4 110 884
31 S 307 1 107 65
6 B 308 5 135 66
57 C 104
45 S 310 7 119 887
59 S 311 4 118 656
62 B 313 4 136 169
26 B 314 7 125 237
30 S 315 7 102 913
28 S 316 8 144 358
4 S 317 3 200 56
33 C 155
12 B 319 6 196 955
3 B 320 3 120 689
54 C 176
44 C 284
13 C 294
13 S 324 7 173 873
43 S 325 4 131 459
32 C 112
4 B 327 9 190 190
30 S 328 2 197 902
13 B 329 8 116 590
58 C 149
21 C 218
40 B 332 7 194 901
43 B 333 6 145 935
63 B 334 9 113 276
30 B 335 9 129 21
22 B 336 2 150 761
27 S 337 4 146 83
10 S 338 1 170 179
58 B 339 2 199 399
35 B 340 5 161 767
21 B 341 3 107 59
63 B 342 4 167 806
17 C 299
45 S 344 3 137 288
55 B 345 6 107 445
18 B 346 1 127 396
1 B 347 0 160 566
55 S 348 6 171 828
41 S 349 2 192 817
47 S 350 5 102 493
31 S 351 1 167 655
12 S 352 3 126 329
1 C 136
28 B 354 3 171 380
45 C 344
45 S 356 7 184 721
42 S 357 5 142 341
4 B 358 2 196 834
30 C 328
36 C 194
62 C 313
52 S 362 5 196 184
1 B 363 8 194 984
51 S 364 7 159 206
10 C 264
35 B 366 8 116 955
30 S 367 4 157 72
51 B 368 7 115 725
40 S 369 2 197 885
22 B 370 1 115 720
23 B 371 7 186 731
23 C 371
28 C 199
29 B 374 0 146 40
6 C 109
61 S 376 1 120 790
1 C 255
53 B 378 5 151 911
17 C 128
54 S 380 6 197 159
6 B 381 5 139 766
35 C 154
62 B 383 4 194 354
57 C 104
22 B 385 6 121 943
17 B 386 5 199 102
57 B 387 0 193 696
55 C 345
11 S 389 3 130 594
46 C 251
55 B 391 9 111 214
30 S 392 9 101 255
24 B 393 5 181 690
31 C 351
57 C 135
51 C 111
32 B 397 9 157 801
56 S 398 0 145 248
38 S 399 6 187 826
21 B 400 7 150 861
18 B 401 1 135 290
54 S 402 1 152 767
55 C 159
11 C 272
13 S 405 5 188 892
57 B 406 4 152 50
34 B 407 1 190 361
37 C 157
54 B 409 8 189 151
56 B 410 7 175 17
54 B 411 0 115 531
54 C 411
51 S 413 9 147 874
34 S 414 5 154 346
3 S 415 9 120 573
14 B 416 8 130 256
55 C 391
36 B 418 3 159 615
0 S 420 4 115 253
17 S 421 7 115 365
42 C 357
24 B 423 8 127 720
5 S 424 4 151 233
27 C 273
35 C 214
0 C 249
52 C 362
52 B 429 5 106 307
22 B 430 8 122 352
5 C 424
4 C 197
43 C 325
44 C 163
24 C 423
13 S 436 4 124 659
29 S 437 8 158 194
50 C 162
47 S 439 6 167 842
11 C 200
49 C 122
11 S 442 0 172 406
55 B 443 7 133 170
41 B 444 4 162 278
20 B 445 3 170 336
53 B 446 8 184 802
63 C 334
59 S 448 6 106 742
33 B 449 3 186 275
17 S 450 5 106 615
45 B 451 6 104 11
8 S 452 8 174 185
53 S 453 1 190 961
61 C 376
34 S 455 2 188 559
56 C 398
33 C 155
21 B 458 3 150 565
31 B 459 5 145 766
49 S 460 3 149 757
23 C 371
37 B 462 0 158 772
16 S 463 4 112 690
37 C 256
6 C 381
28 C 199
62 S 467 6 198 722
2 B 468 4 122 249
12 B 469 6 167 970
29 C 304
43 C 192
33 S 472 4 176 173
17 S 473 2 162 27
43 S 474 4 164 256
18 B 475 8 195 188
4 B 476 2 110 980
31 B 477 5 116 752
20 C 445
7 S 479 4 191 13
9 C 277
1 S 481 0 140 846
33 S 482 5 181 673
51 C 212
35 C 271
41 B 485 8 107 982
18 S 486 8 199 685
3 C 171
60 B 488 1 194 71
34 B 489 0 194 191
23 C 371
27 C 337
52 B 492 0 193 989
24 S 493 7 144 31
44 S 494 9 167 941
2 S 495 1 134 308
42 B 496 4 134 249
19 B 497 9 127 255
57 B 498 7 109 553
49 S 499 6 141 430
31 C 276
13 B 501 4 185 727
3 B 502 5 198 159
49 B 503 2 116 735
2 S 504 7 138 184
6 B 505 3 126 623
40 C 369
24 C 393
63 B 508 2 166 641
23 B 509 2 165 169
57 S 510 8 160 294
24 C 493
13 S 512 8 198 352
13 C 501
18 B 514 3 171 842
22 B 515 5 161 864
50 B 516 8 107 776
42 S 517 1 102 824
11 S 518 4 134 29
32 B 519 5 171 164
9 C 186
30 C 328
13 C 324
4 C 476
28 B 524 9 116 461
12 C 352
45 C 310
50 C 216
12 B 528 3 144 593
49 C 122
17 C 128
40 B 531 9 182 205
57 B 532 6 163 628
0 C 420
51 S 534 9 160 170
30 B 535 9 140 535
49 S 536 9 157 892
2 S 537 6 136 738
60 S 538 3 172 818
1 C 481
30 C 535
39 S 541 8 131 454
44 C 284
29 S 543 9 149 964
57 S 544 4 109 497
35 S 545 2 197 308
5 S 546 5 171 856
51 B 547 2 117 398
27 S 548 1 162 47
27 C 548
15 C 174
55 S 551 9 138 630
52 B 552 1 130 694
12 C 319
2 C 468
37 S 555 1 110 869
31 C 307
14 C 302
0 B 558 2 127 134
42 B 559 0 171 493
19 S 560 6 145 436
29 B 561 4 140 127
17 S 562 0 129 78
37 S 563 2 104 57
2 B 564 5 143 462
47 S 565 6 194 155
22 B 566 4 184 999
61 C 242
38 B 568 2 168 343
25 S 569 5 122 293
38 C 399
59 C 187
26 S 572 9 161 812
3 S 573 3 101 628
62 C 467
9 C 142
49 C 536
44 B 577 3 172 257
19 C 195
50 C 162
59 C 262
29 S 581 8 108 869
2 B 582 5 177 270
38 B 583 4 149 876
47 C 350
20 C 445
5 C 191
4 S 587 9 149 110
6 S 588 1 173 86
12 B 589 2 170 790
43 S 590 7 151 944
0 S 591 6 131 441
8 B 592 0 168 229
58 C 339
25 C 267
3 C 573
50 B 596 1 133 514
63 B 597 8 163 283
48 B 598 4 167 780
13 S 599 2 178 825
3 C 270
36 S 601 8 174 565
43 B 602 4 192 360
51 C 413
49 B 604 7 133 514
62 S 605 7 123 619
37 C 555
23 S 607 4 125 593
17 S 608 3 154 878
10 B 609 6 183 466
3 C 415
32 C 519
44 C 577
19 B 613 4 176 729
17 C 473
7 B 615 6 100 599
41 B 616 4 166 790
4 C 197
38 B 618 3 171 840
39 C 541
38 C 399
29 B 621 9 145 652
53 B 622 2 129 654
22 B 623 0 155 725
12 B 624 6 175 433
24 S 625 5 161 502
37 B 626 8 164 179
56 S 627 5 178 262
63 C 334
51 S 629 1 181 408
34 S 630 5 160 750
28 C 106
9 B 632 8 141 252
53 C 622
10 B 634 8 198 408
16 C 463
5 C 546
37 S 637 6 183 276
18 B 638 4 175 261
51 B 639 7 141 60
20 C 445
7 C 479
7 B 642 0 128 681
